<?xml version="1.0" encoding="utf-8"?>
<!-- This URDF was automatically created by SolidWorks to URDF Exporter! Originally created by Stephen Brawner (brawner@gmail.com) 
     Commit Version: 1.6.0-4-g7f85cfe  Build Version: 1.6.7995.38578
     For more information, please see http://wiki.ros.org/sw_urdf_exporter -->
<robot
  name="ASK-4-5">
  <link
    name="base_link">
    <inertial>
      <origin
        xyz="0.00992946630597225 -0.0026699215350395 0.00139568704685275"
        rpy="0 0 0" />
      <mass
        value="5.13967166144139" />
      <inertia
        ixx="0.0198344939840438"
        ixy="3.68855478958645E-05"
        ixz="-7.51002546313213E-05"
        iyy="0.0149462084052446"
        iyz="7.16569021411617E-05"
        izz="0.0263773506649489" />
    </inertial>
    <visual>
      <origin
        xyz="0 0 0"
        rpy="0 0 0" />
      <geometry>
        <mesh
          filename="package://ASK-4-5/meshes/base_link.STL" />
      </geometry>
      <material
        name="">
        <color
          rgba="0.752941176470588 0.752941176470588 0.752941176470588 1" />
      </material>
    </visual>
    <collision>
      <origin
        xyz="0 0 0"
        rpy="0 0 0" />
      <geometry>
        <mesh
          filename="package://ASK-4-5/meshes/base_link.STL" />
      </geometry>
    </collision>
  </link>
  <link
    name="FL_hip_link">
    <inertial>
      <origin
        xyz="-0.0106503457914954 -0.00105646187245095 7.50117564340957E-06"
        rpy="0 0 0" />
      <mass
        value="0.337654873921649" />
      <inertia
        ixx="0.00033561217232375"
        ixy="5.09865169622585E-06"
        ixz="3.45125064354611E-07"
        iyy="0.000441865005655587"
        iyz="2.04731987900191E-07"
        izz="0.000221802646140032" />
    </inertial>
    <visual>
      <origin
        xyz="0 0 0"
        rpy="0 0 0" />
      <geometry>
        <mesh
          filename="package://ASK-4-5/meshes/FL_hip_link.STL" />
      </geometry>
      <material
        name="">
        <color
          rgba="0.752941176470588 0.752941176470588 0.752941176470588 1" />
      </material>
    </visual>
    <collision>
      <origin
        xyz="0 0 0"
        rpy="0 0 0" />
      <geometry>
        <mesh
          filename="package://ASK-4-5/meshes/FL_hip_link.STL" />
      </geometry>
    </collision>
  </link>
  <joint
    name="FL_hip_joint"
    type="revolute">
    <origin
      xyz="0.209 0.0575000000000031 0"
      rpy="0 0 0" />
    <parent
      link="base_link" />
    <child
      link="FL_hip_link" />
    <axis
      xyz="1 0 0" />
    <limit
      lower="-3.14"
      upper="3.14"
      effort="100"
      velocity="100" />
  </joint>
  <link
    name="FL_thigh_link">
    <inertial>
      <origin
        xyz="0.0251391100869524 -0.0232842260848743 0.0118252095018475"
        rpy="0 0 0" />
      <mass
        value="0.988517367587917" />
      <inertia
        ixx="0.000945791898412224"
        ixy="3.06631858737655E-06"
        ixz="-0.000697814598250291"
        iyy="0.00302059797576065"
        iyz="7.09784988441869E-07"
        izz="0.00227101573244348" />
    </inertial>
    <visual>
      <origin
        xyz="0 0 0"
        rpy="0 0 0" />
      <geometry>
        <mesh
          filename="package://ASK-4-5/meshes/FL_thigh_link.STL" />
      </geometry>
      <material
        name="">
        <color
          rgba="0.752941176470588 0.752941176470588 0.752941176470588 1" />
      </material>
    </visual>
    <collision>
      <origin
        xyz="0 0 0"
        rpy="0 0 0" />
      <geometry>
        <mesh
          filename="package://ASK-4-5/meshes/FL_thigh_link.STL" />
      </geometry>
    </collision>
  </link>
  <joint
    name="FL_thigh_joint"
    type="revolute">
    <origin
      xyz="0 0.0975 0"
      rpy="3.14159265358979 1.16418582684397 3.14159265358979" />
    <parent
      link="FL_hip_link" />
    <child
      link="FL_thigh_link" />
    <axis
      xyz="0 1 0" />
    <limit
      lower="-3.14"
      upper="3.14"
      effort="100"
      velocity="100" />
  </joint>
  <link
    name="FL_calf_link">
    <inertial>
      <origin
        xyz="0.00461061452147504 1.80400082971932E-06 -0.085011296004844"
        rpy="0 0 0" />
      <mass
        value="0.19650888449556" />
      <inertia
        ixx="0.00139217885927767"
        ixy="-2.06452748563679E-09"
        ixz="0.000125545815699013"
        iyy="0.00143103513567007"
        iyz="4.12063854285578E-08"
        izz="4.99156816168517E-05" />
    </inertial>
    <visual>
      <origin
        xyz="0 0 0"
        rpy="0 0 0" />
      <geometry>
        <mesh
          filename="package://ASK-4-5/meshes/FL_calf_link.STL" />
      </geometry>
      <material
        name="">
        <color
          rgba="0.898039215686275 0.917647058823529 0.929411764705882 1" />
      </material>
    </visual>
    <collision>
      <origin
        xyz="0 0 0"
        rpy="0 0 0" />
      <geometry>
        <mesh
          filename="package://ASK-4-5/meshes/FL_calf_link.STL" />
      </geometry>
    </collision>
  </link>
  <joint
    name="FL_calf_joint"
    type="revolute">
    <origin
      xyz="0.192877994043746 -0.00100000000000014 0.0830546772533787"
      rpy="-3.14159265358979 -1.16418582684397 3.14159265358979" />
    <parent
      link="FL_thigh_link" />
    <child
      link="FL_calf_link" />
    <axis
      xyz="0 -1 0" />
    <limit
      lower="-3.14"
      upper="3.14"
      effort="100"
      velocity="100" />
  </joint>
  <link
    name="FL_foot_link">
    <inertial>
      <origin
        xyz="-0.00175459486820176 0 -0.00179543551506534"
        rpy="0 0 0" />
      <mass
        value="0.0332506166455944" />
      <inertia
        ixx="5.82412671981776E-06"
        ixy="5.25372922423827E-22"
        ixz="6.37425175827703E-07"
        iyy="5.20120101015828E-06"
        iyz="-8.28398746420858E-23"
        izz="5.85346314748617E-06" />
    </inertial>
    <visual>
      <origin
        xyz="0 0 0"
        rpy="0 0 0" />
      <geometry>
        <mesh
          filename="package://ASK-4-5/meshes/FL_foot_link.STL" />
      </geometry>
      <material
        name="">
        <color
          rgba="0.298039215686275 0.298039215686275 0.298039215686275 1" />
      </material>
    </visual>
    <collision>
      <origin
        xyz="0 0 0"
        rpy="0 0 0" />
      <geometry>
        <mesh
          filename="package://ASK-4-5/meshes/FL_foot_link.STL" />
      </geometry>
    </collision>
  </link>
  <joint
    name="FL_foot_joint"
    type="fixed">
    <origin
      xyz="0 0 -0.215773231361156"
      rpy="0 0 0" />
    <parent
      link="FL_calf_link" />
    <child
      link="FL_foot_link" />
    <axis
      xyz="0 0 0" />
  </joint>
  <link
    name="FR_hip_link">
    <inertial>
      <origin
        xyz="-0.0106669389296382 0.00105654727697249 -8.09717352479034E-06"
        rpy="0 0 0" />
      <mass
        value="0.337657104489193" />
      <inertia
        ixx="0.000335667809975768"
        ixy="-5.0083024033389E-06"
        ixz="3.52480310375702E-07"
        iyy="0.000441866858701043"
        iyz="-1.15542052465363E-07"
        izz="0.000221750529456321" />
    </inertial>
    <visual>
      <origin
        xyz="0 0 0"
        rpy="0 0 0" />
      <geometry>
        <mesh
          filename="package://ASK-4-5/meshes/FR_hip_link.STL" />
      </geometry>
      <material
        name="">
        <color
          rgba="0.752941176470588 0.752941176470588 0.752941176470588 1" />
      </material>
    </visual>
    <collision>
      <origin
        xyz="0 0 0"
        rpy="0 0 0" />
      <geometry>
        <mesh
          filename="package://ASK-4-5/meshes/FR_hip_link.STL" />
      </geometry>
    </collision>
  </link>
  <joint
    name="FR_hip_joint"
    type="revolute">
    <origin
      xyz="0.209000000000005 -0.0574999999999968 0"
      rpy="0 0 0" />
    <parent
      link="base_link" />
    <child
      link="FR_hip_link" />
    <axis
      xyz="1 0 0" />
    <limit
      lower="-3.14"
      upper="3.14"
      effort="100"
      velocity="100" />
  </joint>
  <link
    name="FR_thigh_link">
    <inertial>
      <origin
        xyz="-0.000547030558334965 0.0233673926903711 -0.0276872735698288"
        rpy="0 0 0" />
      <mass
        value="0.981796539065315" />
      <inertia
        ixx="0.00253399649905657"
        ixy="-7.20203197026017E-08"
        ixz="-2.1250527799311E-05"
        iyy="0.00298771577286461"
        iyz="4.13998861188547E-06"
        izz="0.000649782763434764" />
    </inertial>
    <visual>
      <origin
        xyz="0 0 0"
        rpy="0 0 0" />
      <geometry>
        <mesh
          filename="package://ASK-4-5/meshes/FR_thigh_link.STL" />
      </geometry>
      <material
        name="">
        <color
          rgba="0.752941176470588 0.752941176470588 0.752941176470588 1" />
      </material>
    </visual>
    <collision>
      <origin
        xyz="0 0 0"
        rpy="0 0 0" />
      <geometry>
        <mesh
          filename="package://ASK-4-5/meshes/FR_thigh_link.STL" />
      </geometry>
    </collision>
  </link>
  <joint
    name="FR_thigh_joint"
    type="revolute">
    <origin
      xyz="0 -0.0975 0"
      rpy="0 0 0" />
    <parent
      link="FR_hip_link" />
    <child
      link="FR_thigh_link" />
    <axis
      xyz="0 -1 0" />
    <limit
      lower="-3.14"
      upper="3.14"
      effort="100"
      velocity="100" />
  </joint>
  <link
    name="FR_calf_link">
    <inertial>
      <origin
        xyz="0.00461061452147521 1.80400082962218E-06 -0.0850112960048446"
        rpy="0 0 0" />
      <mass
        value="0.196508884495562" />
      <inertia
        ixx="0.00139217885927767"
        ixy="-2.06452748616008E-09"
        ixz="0.000125545815699016"
        iyy="0.00143103513567006"
        iyz="4.12063854271999E-08"
        izz="4.99156816168345E-05" />
    </inertial>
    <visual>
      <origin
        xyz="0 0 0"
        rpy="0 0 0" />
      <geometry>
        <mesh
          filename="package://ASK-4-5/meshes/FR_calf_link.STL" />
      </geometry>
      <material
        name="">
        <color
          rgba="0.898039215686275 0.917647058823529 0.929411764705882 1" />
      </material>
    </visual>
    <collision>
      <origin
        xyz="0 0 0"
        rpy="0 0 0" />
      <geometry>
        <mesh
          filename="package://ASK-4-5/meshes/FR_calf_link.STL" />
      </geometry>
    </collision>
  </link>
  <joint
    name="FR_calf_joint"
    type="revolute">
    <origin
      xyz="0 0.00100000000000315 -0.210000000000006"
      rpy="0 0 0" />
    <parent
      link="FR_thigh_link" />
    <child
      link="FR_calf_link" />
    <axis
      xyz="0 -1 0" />
    <limit
      lower="-3.14"
      upper="3.14"
      effort="100"
      velocity="100" />
  </joint>
  <link
    name="FR_foot_link">
    <inertial>
      <origin
        xyz="-0.00175459486820173 1.38777878078145E-17 -0.00182803153806099"
        rpy="0 0 0" />
      <mass
        value="0.0332506166455944" />
      <inertia
        ixx="5.82412671981776E-06"
        ixy="-3.78318670790692E-22"
        ixz="6.37425175827702E-07"
        iyy="5.20120101015829E-06"
        iyz="-5.62985280037846E-22"
        izz="5.85346314748617E-06" />
    </inertial>
    <visual>
      <origin
        xyz="0 0 0"
        rpy="0 0 0" />
      <geometry>
        <mesh
          filename="package://ASK-4-5/meshes/FR_foot_link.STL" />
      </geometry>
      <material
        name="">
        <color
          rgba="0.298039215686275 0.298039215686275 0.298039215686275 1" />
      </material>
    </visual>
    <collision>
      <origin
        xyz="0 0 0"
        rpy="0 0 0" />
      <geometry>
        <mesh
          filename="package://ASK-4-5/meshes/FR_foot_link.STL" />
      </geometry>
    </collision>
  </link>
  <joint
    name="FR_foot_joint"
    type="fixed">
    <origin
      xyz="0 0 -0.21574063533816"
      rpy="0 0 0" />
    <parent
      link="FR_calf_link" />
    <child
      link="FR_foot_link" />
    <axis
      xyz="0 0 0" />
  </joint>
  <link
    name="RL_hip_link">
    <inertial>
      <origin
        xyz="0.0106503460334456 -0.00105646148572418 -7.50181891534529E-06"
        rpy="0 0 0" />
      <mass
        value="0.33765486830875" />
      <inertia
        ixx="0.000335612160621357"
        ixy="-5.09864760893828E-06"
        ixz="3.4511770749044E-07"
        iyy="0.000441864990334726"
        iyz="-2.04736902744757E-07"
        izz="0.00022180263729175" />
    </inertial>
    <visual>
      <origin
        xyz="0 0 0"
        rpy="0 0 0" />
      <geometry>
        <mesh
          filename="package://ASK-4-5/meshes/RL_hip_link.STL" />
      </geometry>
      <material
        name="">
        <color
          rgba="0.752941176470588 0.752941176470588 0.752941176470588 1" />
      </material>
    </visual>
    <collision>
      <origin
        xyz="0 0 0"
        rpy="0 0 0" />
      <geometry>
        <mesh
          filename="package://ASK-4-5/meshes/RL_hip_link.STL" />
      </geometry>
    </collision>
  </link>
  <joint
    name="RL_hip_joint"
    type="revolute">
    <origin
      xyz="-0.212 0.0575000000000033 0"
      rpy="0 0 0" />
    <parent
      link="base_link" />
    <child
      link="RL_hip_link" />
    <axis
      xyz="-1 0 0" />
    <limit
      lower="-3.14"
      upper="3.14"
      effort="100"
      velocity="100" />
  </joint>
  <link
    name="RL_thigh_link">
    <inertial>
      <origin
        xyz="0.000408227545235923 0.0232833165047042 -0.0284358553099156"
        rpy="0 0 0" />
      <mass
        value="0.988547565628561" />
      <inertia
        ixx="0.00255264500112582"
        ixy="-9.8665731606502E-07"
        ixz="9.82930312946654E-05"
        iyy="0.00302059853537961"
        iyz="2.6889597970943E-06"
        izz="0.000664162957356105" />
    </inertial>
    <visual>
      <origin
        xyz="0 0 0"
        rpy="0 0 0" />
      <geometry>
        <mesh
          filename="package://ASK-4-5/meshes/RL_thigh_link.STL" />
      </geometry>
      <material
        name="">
        <color
          rgba="0.752941176470588 0.752941176470588 0.752941176470588 1" />
      </material>
    </visual>
    <collision>
      <origin
        xyz="0 0 0"
        rpy="0 0 0" />
      <geometry>
        <mesh
          filename="package://ASK-4-5/meshes/RL_thigh_link.STL" />
      </geometry>
    </collision>
  </link>
  <joint
    name="RL_thigh_joint"
    type="revolute">
    <origin
      xyz="0 0.0974999999999997 0"
      rpy="0 0.0393393013816893 3.14159265358979" />
    <parent
      link="RL_hip_link" />
    <child
      link="RL_thigh_link" />
    <axis
      xyz="0 -1 0" />
    <limit
      lower="0"
      upper="0"
      effort="0"
      velocity="0" />
  </joint>
  <link
    name="RL_calf_link">
    <inertial>
      <origin
        xyz="0.00461061452147501 1.80400082944177E-06 -0.0850112960048451"
        rpy="0 0 0" />
      <mass
        value="0.196508884495564" />
      <inertia
        ixx="0.00139217885927768"
        ixy="-2.06452748671287E-09"
        ixz="0.000125545815699013"
        iyy="0.00143103513567009"
        iyz="4.12063854261151E-08"
        izz="4.99156816168485E-05" />
    </inertial>
    <visual>
      <origin
        xyz="0 0 0"
        rpy="0 0 0" />
      <geometry>
        <mesh
          filename="package://ASK-4-5/meshes/RL_calf_link.STL" />
      </geometry>
      <material
        name="">
        <color
          rgba="0.898039215686275 0.917647058823529 0.929411764705882 1" />
      </material>
    </visual>
    <collision>
      <origin
        xyz="0 0 0"
        rpy="0 0 0" />
      <geometry>
        <mesh
          filename="package://ASK-4-5/meshes/RL_calf_link.STL" />
      </geometry>
    </collision>
  </link>
  <joint
    name="RL_calf_joint"
    type="revolute">
    <origin
      xyz="0.00825912262911521 0.00100000000000011 -0.209837524988716"
      rpy="0 0.0393393013816893 3.14159265358979" />
    <parent
      link="RL_thigh_link" />
    <child
      link="RL_calf_link" />
    <axis
      xyz="0 -1 0" />
    <limit
      lower="0"
      upper="0"
      effort="0"
      velocity="0" />
  </joint>
  <link
    name="RL_foot_link">
    <inertial>
      <origin
        xyz="-0.0017545948682017 0 -0.00179543551506522"
        rpy="0 0 0" />
      <mass
        value="0.0332506166455944" />
      <inertia
        ixx="5.82412671981776E-06"
        ixy="-2.08372416049388E-22"
        ixz="6.37425175827703E-07"
        iyy="5.20120101015829E-06"
        iyz="-4.22786611841748E-22"
        izz="5.85346314748617E-06" />
    </inertial>
    <visual>
      <origin
        xyz="0 0 0"
        rpy="0 0 0" />
      <geometry>
        <mesh
          filename="package://ASK-4-5/meshes/RL_foot_link.STL" />
      </geometry>
      <material
        name="">
        <color
          rgba="0.298039215686275 0.298039215686275 0.298039215686275 1" />
      </material>
    </visual>
    <collision>
      <origin
        xyz="0 0 0"
        rpy="0 0 0" />
      <geometry>
        <mesh
          filename="package://ASK-4-5/meshes/RL_foot_link.STL" />
      </geometry>
    </collision>
  </link>
  <joint
    name="RL_foot_joint"
    type="fixed">
    <origin
      xyz="0 0 -0.215773231361156"
      rpy="0 0 0" />
    <parent
      link="RL_calf_link" />
    <child
      link="RL_foot_link" />
    <axis
      xyz="0 0 0" />
  </joint>
  <link
    name="RR_hip_link">
    <inertial>
      <origin
        xyz="0.0106669389296382 0.00105654727697253 8.09717352490136E-06"
        rpy="0 0 0" />
      <mass
        value="0.337657104489195" />
      <inertia
        ixx="0.00033566780997577"
        ixy="5.00830240333875E-06"
        ixz="3.52480310375446E-07"
        iyy="0.000441866858701045"
        iyz="1.15542052465259E-07"
        izz="0.000221750529456321" />
    </inertial>
    <visual>
      <origin
        xyz="0 0 0"
        rpy="0 0 0" />
      <geometry>
        <mesh
          filename="package://ASK-4-5/meshes/RR_hip_link.STL" />
      </geometry>
      <material
        name="">
        <color
          rgba="0.752941176470588 0.752941176470588 0.752941176470588 1" />
      </material>
    </visual>
    <collision>
      <origin
        xyz="0 0 0"
        rpy="0 0 0" />
      <geometry>
        <mesh
          filename="package://ASK-4-5/meshes/RR_hip_link.STL" />
      </geometry>
    </collision>
  </link>
  <joint
    name="RR_hip_joint"
    type="revolute">
    <origin
      xyz="-0.212000000000005 -0.057499999999997 0"
      rpy="0 0 0" />
    <parent
      link="base_link" />
    <child
      link="RR_hip_link" />
    <axis
      xyz="-1 0 0" />
    <limit
      lower="-3.14"
      upper="3.14"
      effort="100"
      velocity="100" />
  </joint>
  <link
    name="RR_thigh_link">
    <inertial>
      <origin
        xyz="-0.000517951451789178 0.0233673926042728 -0.0285202572103428"
        rpy="0 0 0" />
      <mass
        value="0.981796539396403" />
      <inertia
        ixx="0.00253108517803927"
        ixy="1.75361348996199E-07"
        ixz="7.52244066710027E-06"
        iyy="0.00298771577306385"
        iyz="3.6497590105567E-06"
        izz="0.000652694084685841" />
    </inertial>
    <visual>
      <origin
        xyz="0 0 0"
        rpy="0 0 0" />
      <geometry>
        <mesh
          filename="package://ASK-4-5/meshes/RR_thigh_link.STL" />
      </geometry>
      <material
        name="">
        <color
          rgba="0.752941176470588 0.752941176470588 0.752941176470588 1" />
      </material>
    </visual>
    <collision>
      <origin
        xyz="0 0 0"
        rpy="0 0 0" />
      <geometry>
        <mesh
          filename="package://ASK-4-5/meshes/RR_thigh_link.STL" />
      </geometry>
    </collision>
  </link>
  <joint
    name="RR_thigh_joint"
    type="revolute">
    <origin
      xyz="0 -0.0975 0"
      rpy="0 0 0" />
    <parent
      link="RR_hip_link" />
    <child
      link="RR_thigh_link" />
    <axis
      xyz="0 -1 0" />
    <limit
      lower="-3.14"
      upper="3.14"
      effort="100"
      velocity="100" />
  </joint>
  <link
    name="RR_calf_link">
    <inertial>
      <origin
        xyz="0.00461061452147515 1.80400082963605E-06 -0.0850112960048445"
        rpy="0 0 0" />
      <mass
        value="0.196508884495561" />
      <inertia
        ixx="0.00139217885927767"
        ixy="-2.06452748590148E-09"
        ixz="0.000125545815699014"
        iyy="0.00143103513567006"
        iyz="4.12063854269123E-08"
        izz="4.9915681616837E-05" />
    </inertial>
    <visual>
      <origin
        xyz="0 0 0"
        rpy="0 0 0" />
      <geometry>
        <mesh
          filename="package://ASK-4-5/meshes/RR_calf_link.STL" />
      </geometry>
      <material
        name="">
        <color
          rgba="0.898039215686275 0.917647058823529 0.929411764705882 1" />
      </material>
    </visual>
    <collision>
      <origin
        xyz="0 0 0"
        rpy="0 0 0" />
      <geometry>
        <mesh
          filename="package://ASK-4-5/meshes/RR_calf_link.STL" />
      </geometry>
    </collision>
  </link>
  <joint
    name="RR_calf_joint"
    type="revolute">
    <origin
      xyz="0 0.00100000000000035 -0.210000000000027"
      rpy="0 0 0" />
    <parent
      link="RR_thigh_link" />
    <child
      link="RR_calf_link" />
    <axis
      xyz="0 -1 0" />
    <limit
      lower="-3.14"
      upper="3.14"
      effort="100"
      velocity="100" />
  </joint>
  <link
    name="RR_foot_link">
    <inertial>
      <origin
        xyz="-0.00175459486820173 0 -0.00179543551506522"
        rpy="0 0 0" />
      <mass
        value="0.0332506166455944" />
      <inertia
        ixx="5.82412671981776E-06"
        ixy="-1.67264437396789E-23"
        ixz="6.37425175827701E-07"
        iyy="5.20120101015829E-06"
        iyz="4.9536863091819E-22"
        izz="5.85346314748617E-06" />
    </inertial>
    <visual>
      <origin
        xyz="0 0 0"
        rpy="0 0 0" />
      <geometry>
        <mesh
          filename="package://ASK-4-5/meshes/RR_foot_link.STL" />
      </geometry>
      <material
        name="">
        <color
          rgba="0.298039215686275 0.298039215686275 0.298039215686275 1" />
      </material>
    </visual>
    <collision>
      <origin
        xyz="0 0 0"
        rpy="0 0 0" />
      <geometry>
        <mesh
          filename="package://ASK-4-5/meshes/RR_foot_link.STL" />
      </geometry>
    </collision>
  </link>
  <joint
    name="RR_foot_joint"
    type="fixed">
    <origin
      xyz="0 0 -0.215773231361156"
      rpy="0 0 0" />
    <parent
      link="RR_calf_link" />
    <child
      link="RR_foot_link" />
    <axis
      xyz="0 0 0" />
  </joint>
</robot>