<?xml version="1.0" encoding="utf-8"?>
<!-- This URDF was automatically created by SolidWorks to URDF Exporter! Originally created by Stephen Brawner (brawner@gmail.com) 
     Commit Version: 1.6.0-4-g7f85cfe  Build Version: 1.6.7995.38578
     For more information, please see http://wiki.ros.org/sw_urdf_exporter -->
<robot
  name="ASK-4-3">
    <mujoco>
  <compiler 
    meshdir="/home/pi/Downloads/LocomotionWithNP3O-master/resources/tinymal/meshes" 
    balanceinertia="true" 
    discardvisual="false" />
</mujoco>
  <link name="dummy_link"/>
<joint name="dummy_joint" type="fixed">
  <parent link="dummy_link"/>
  <child link="base_link"/>
</joint>
  <link
    name="base_link">
    <inertial>
      <origin
        xyz="0.00992946630597225 -0.0026699215350395 0.00139568704685275"
        rpy="0 0 0" />
      <mass
        value="5.13967166144139" />
      <inertia
        ixx="0.0198344939840438"
        ixy="3.68855478958649E-05"
        ixz="-7.51002546313216E-05"
        iyy="0.0149462084052446"
        iyz="7.16569021411598E-05"
        izz="0.0263773506649489" />
    </inertial>
    <visual>
      <origin
        xyz="0 0 0"
        rpy="0 0 0" />
      <geometry>
        <mesh
          filename="package://urdf_tutorial/meshes/base_link.STL" />
      </geometry>
      <material
        name="">
        <color
          rgba="0.752941176470588 0.752941176470588 0.752941176470588 1" />
      </material>
    </visual>
    <collision>
      <origin
        xyz="0 0 0"
        rpy="0 0 0" />
      <geometry>
        <mesh
          filename="package://urdf_tutorial/meshes/base_link.STL" />
      </geometry>
    </collision>
  </link>
  <link
    name="FL_hip_link">
    <inertial>
      <origin
        xyz="-0.0106503457914953 -0.00105646187245094 7.50117564338182E-06"
        rpy="0 0 0" />
      <mass
        value="0.337654873921649" />
      <inertia
        ixx="0.00033561217232375"
        ixy="5.09865169622584E-06"
        ixz="3.45125064354608E-07"
        iyy="0.000441865005655587"
        iyz="2.047319879002E-07"
        izz="0.000221802646140032" />
    </inertial>
    <visual>
      <origin
        xyz="0 0 0"
        rpy="0 0 0" />
      <geometry>
        <mesh
          filename="package://urdf_tutorial/meshes/hip_link.STL" />
      </geometry>
      <material
        name="">
        <color
          rgba="0.752941176470588 0.752941176470588 0.752941176470588 1" />
      </material>
    </visual>
    <collision>
      <origin
        xyz="0 0 0"
        rpy="0 0 0" />
      <geometry>
        <mesh
          filename="package://urdf_tutorial/meshes/hip_link.STL" />
      </geometry>
    </collision>
  </link>
  <joint
    name="FL_hip_joint"
    type="revolute">
    <origin
      xyz="0.209 0.0575 0"
      rpy="0 0 0" />
    <parent
      link="base_link" />
    <child
      link="FL_hip_link" />
    <axis
      xyz="1 0 0" />
    <limit
      lower="-3.14"
      upper="3.14"
      effort="100"
      velocity="100" />
  </joint>
  <link
    name="FL_thigh_link">
    <inertial>
      <origin
        xyz="-0.00154194605367627 -0.0232842260902867 -0.0288190699212917"
        rpy="0 0 0" />
      <mass
        value="0.988517367360061" />
      <inertia
        ixx="0.00256066309935582"
        ixy="2.60983728498532E-07"
        ixz="4.30041414954873E-05"
        iyy="0.00302059797548256"
        iyz="-2.27178654868997E-06"
        izz="0.000656144531218472" />
    </inertial>
    <visual>
      <origin
        xyz="0 0 0"
        rpy="0 0 0" />
      <geometry>
        <mesh
          filename="package://urdf_tutorial/meshes/thigh_link.STL" />
      </geometry>
      <material
        name="">
        <color
          rgba="0.752941176470588 0.752941176470588 0.752941176470588 1" />
      </material>
    </visual>
    <collision>
      <origin
        xyz="0 0 0"
        rpy="0 0 0" />
      <geometry>
        <mesh
          filename="package://urdf_tutorial/meshes/thigh_link.STL" />
      </geometry>
    </collision>
  </link>
  <joint
    name="FL_thigh_joint"
    type="revolute">
    <origin
      xyz="0 0.0975 0"
      rpy="0 0 0" />
    <parent
      link="FL_hip_link" />
    <child
      link="FL_thigh_link" />
    <axis
      xyz="0 1 0" />
    <limit
      lower="-3.14"
      upper="3.14"
      effort="100"
      velocity="100" />
  </joint>
  <link
    name="FL_calf_link">
    <inertial>
      <origin
        xyz="0.00461061452147496 1.80400082958054E-06 -0.0850112960048433"
        rpy="0 0 0" />
      <mass
        value="0.19650888449556" />
      <inertia
        ixx="0.00139217885927766"
        ixy="-2.06452748584044E-09"
        ixz="0.000125545815699013"
        iyy="0.00143103513567006"
        iyz="4.12063854275478E-08"
        izz="4.99156816168528E-05" />
    </inertial>
    <visual>
      <origin
        xyz="0 0 0"
        rpy="0 0 0" />
      <geometry>
        <mesh
          filename="package://urdf_tutorial/meshes/calf_link.STL" />
      </geometry>
      <material
        name="">
        <color
          rgba="0.898039215686275 0.917647058823529 0.929411764705882 1" />
      </material>
    </visual>
    <collision>
      <origin
        xyz="0 0 0"
        rpy="0 0 0" />
      <geometry>
        <mesh
          filename="package://urdf_tutorial/meshes/calf_link.STL" />
      </geometry>
    </collision>
  </link>
  <joint
    name="FL_calf_joint"
    type="revolute">
    <origin
      xyz="0 -0.001 -0.21"
      rpy="0 0 0" />
    <parent
      link="FL_thigh_link" />
    <child
      link="FL_calf_link" />
    <axis
      xyz="0 -1 0" />
    <limit
      lower="-3.14"
      upper="3.14"
      effort="100"
      velocity="100" />
  </joint>
  <link
    name="FL_foot_link">
    <inertial>
      <origin
        xyz="-0.00175459486820176 0 -0.00179543551506534"
        rpy="0 0 0" />
      <mass
        value="0.0332506166455944" />
      <inertia
        ixx="5.82412671981776E-06"
        ixy="6.40470714281943E-22"
        ixz="6.37425175827703E-07"
        iyy="5.20120101015828E-06"
        iyz="-1.55308179837147E-22"
        izz="5.85346314748617E-06" />
    </inertial>
    <visual>
      <origin
        xyz="0 0 0"
        rpy="0 0 0" />
      <geometry>
        <mesh
          filename="package://urdf_tutorial/meshes/foot_link.STL" />
      </geometry>
      <material
        name="">
        <color
          rgba="0.298039215686275 0.298039215686275 0.298039215686275 1" />
      </material>
    </visual>
    <collision>
      <origin
        xyz="0 0 0"
        rpy="0 0 0" />
      <geometry>
        <mesh
          filename="package://urdf_tutorial/meshes/foot_link.STL" />
      </geometry>
    </collision>
  </link>
  <joint
    name="FL_foot_joint"
    type="fixed">
    <origin
      xyz="0 0 -0.21577"
      rpy="0 0 0" />
    <parent
      link="FL_calf_link" />
    <child
      link="FL_foot_link" />
    <axis
      xyz="0 0 0" />
  </joint>
  <link
    name="FR_hip_link">
    <inertial>
      <origin
        xyz="-0.0106669389296382 0.00105654727697248 -8.09717352481809E-06"
        rpy="0 0 0" />
      <mass
        value="0.337657104489193" />
      <inertia
        ixx="0.000335667809975768"
        ixy="-5.00830240333889E-06"
        ixz="3.52480310375706E-07"
        iyy="0.000441866858701043"
        iyz="-1.15542052465369E-07"
        izz="0.000221750529456321" />
    </inertial>
    <visual>
      <origin
        xyz="0 0 0"
        rpy="0 0 0" />
      <geometry>
        <mesh
          filename="package://urdf_tutorial/meshes/R_hip_link.STL" />
      </geometry>
      <material
        name="">
        <color
          rgba="0.752941176470588 0.752941176470588 0.752941176470588 1" />
      </material>
    </visual>
    <collision>
      <origin
        xyz="0 0 0"
        rpy="0 0 0" />
      <geometry>
        <mesh
          filename="package://urdf_tutorial/meshes/R_hip_link.STL" />
      </geometry>
    </collision>
  </link>
  <joint
    name="FR_hip_joint"
    type="revolute">
    <origin
      xyz="0.209 -0.0575 0"
      rpy="0 0 0" />
    <parent
      link="base_link" />
    <child
      link="FR_hip_link" />
    <axis
      xyz="1 0 0" />
    <limit
      lower="-3.14"
      upper="3.14"
      effort="100"
      velocity="100" />
  </joint>
  <link
    name="FR_thigh_link">
    <inertial>
      <origin
        xyz="-0.000547030529932935 0.0234020992927097 -0.0276872735759748"
        rpy="0 0 0" />
      <mass
        value="0.981796539065316" />
      <inertia
        ixx="0.00253399649905652"
        ixy="-7.20203198190831E-08"
        ixz="-2.12505277994908E-05"
        iyy="0.00298771577286478"
        iyz="4.1399886120596E-06"
        izz="0.000649782763434869" />
    </inertial>
    <visual>
      <origin
        xyz="0 0 0"
        rpy="0 0 0" />
      <geometry>
        <mesh
          filename="package://urdf_tutorial/meshes/R_thigh_link.STL" />
      </geometry>
      <material
        name="">
        <color
          rgba="0.752941176470588 0.752941176470588 0.752941176470588 1" />
      </material>
    </visual>
    <collision>
      <origin
        xyz="0 0 0"
        rpy="0 0 0" />
      <geometry>
        <mesh
          filename="package://urdf_tutorial/meshes/R_thigh_link.STL" />
      </geometry>
    </collision>
  </link>
  <joint
    name="FR_thigh_joint"
    type="revolute">
    <origin
      xyz="0 -0.10672 0"
      rpy="0 0 0" />
    <parent
      link="FR_hip_link" />
    <child
      link="FR_thigh_link" />
    <axis
      xyz="0 -1 0" />
    <limit
      lower="-3.14"
      upper="3.14"
      effort="100"
      velocity="100" />
  </joint>
  <link
    name="FR_calf_link">
    <inertial>
      <origin
        xyz="0.00461061452147513 1.80400082958054E-06 -0.0850112960048443"
        rpy="0 0 0" />
      <mass
        value="0.196508884495562" />
      <inertia
        ixx="0.00139217885927767"
        ixy="-2.06452748610362E-09"
        ixz="0.000125545815699015"
        iyy="0.00143103513567006"
        iyz="4.12063854270909E-08"
        izz="4.99156816168349E-05" />
    </inertial>
    <visual>
      <origin
        xyz="0 0 0"
        rpy="0 0 0" />
      <geometry>
        <mesh
          filename="package://urdf_tutorial/meshes/calf_link.STL" />
      </geometry>
      <material
        name="">
        <color
          rgba="0.898039215686275 0.917647058823529 0.929411764705882 1" />
      </material>
    </visual>
    <collision>
      <origin
        xyz="0 0 0"
        rpy="0 0 0" />
      <geometry>
        <mesh
          filename="package://urdf_tutorial/meshes/calf_link.STL" />
      </geometry>
    </collision>
  </link>
  <joint
    name="FR_calf_joint"
    type="revolute">
    <origin
      xyz="0 0.001 -0.21"
      rpy="0 0 0" />
    <parent
      link="FR_thigh_link" />
    <child
      link="FR_calf_link" />
    <axis
      xyz="0 -1 0" />
    <limit
      lower="-3.14"
      upper="3.14"
      effort="100"
      velocity="100" />
  </joint>
  <link
    name="FR_foot_link">
    <inertial>
      <origin
        xyz="-0.00175459486820176 0 -0.00182803153806099"
        rpy="0 0 0" />
      <mass
        value="0.0332506166455943" />
      <inertia
        ixx="5.82412671981775E-06"
        ixy="3.90642345069643E-22"
        ixz="6.37425175827702E-07"
        iyy="5.20120101015827E-06"
        iyz="2.65923868636214E-22"
        izz="5.85346314748616E-06" />
    </inertial>
    <visual>
      <origin
        xyz="0 0 0"
        rpy="0 0 0" />
      <geometry>
        <mesh
          filename="package://urdf_tutorial/meshes/foot_link.STL" />
      </geometry>
      <material
        name="">
        <color
          rgba="0.298039215686275 0.298039215686275 0.298039215686275 1" />
      </material>
    </visual>
    <collision>
      <origin
        xyz="0 0 0"
        rpy="0 0 0" />
      <geometry>
        <mesh
          filename="package://urdf_tutorial/meshes/foot_link.STL" />
      </geometry>
    </collision>
  </link>
  <joint
    name="FR_foot_joint"
    type="fixed">
    <origin
      xyz="0 0 -0.21574"
      rpy="0 0 0" />
    <parent
      link="FR_calf_link" />
    <child
      link="FR_foot_link" />
    <axis
      xyz="0 0 0" />
  </joint>
  <link
    name="RL_hip_link">
    <inertial>
      <origin
        xyz="0.0106503460334455 -0.00105646148572416 -7.50181891534529E-06"
        rpy="0 0 0" />
      <mass
        value="0.33765486830875" />
      <inertia
        ixx="0.000335612160621357"
        ixy="-5.09864760893827E-06"
        ixz="3.45117707490441E-07"
        iyy="0.000441864990334726"
        iyz="-2.04736902744755E-07"
        izz="0.00022180263729175" />
    </inertial>
    <visual>
      <origin
        xyz="0 0 0"
        rpy="0 0 0" />
      <geometry>
        <mesh
          filename="package://urdf_tutorial/meshes/hip_link.STL" />
      </geometry>
      <material
        name="">
        <color
          rgba="0.752941176470588 0.752941176470588 0.752941176470588 1" />
      </material>
    </visual>
    <collision>
      <origin
        xyz="0 0 0"
        rpy="0 0 0" />
      <geometry>
        <mesh
          filename="package://urdf_tutorial/meshes/hip_link.STL" />
      </geometry>
    </collision>
  </link>
  <joint
    name="RL_hip_joint"
    type="revolute">
    <origin
      xyz="-0.212 0.0575000000000033 0"
      rpy="0 0 0" />
    <parent
      link="base_link" />
    <child
      link="RL_hip_link" />
    <axis
      xyz="-1 0 0" />
    <limit
      lower="-3.14"
      upper="3.14"
      effort="100"
      velocity="100" />
  </joint>
  <link
    name="RL_thigh_link">
    <inertial>
      <origin
        xyz="-0.000408227537384398 -0.0232833165056859 -0.0284358553279452"
        rpy="0 0 0" />
      <mass
        value="0.988547565363266" />
      <inertia
        ixx="0.00255264500098736"
        ixy="-9.86657364987751E-07"
        ixz="-9.82930313809756E-05"
        iyy="0.00302059853519443"
        iyz="-2.68895973980838E-06"
        izz="0.000664162957246136" />
    </inertial>
    <visual>
      <origin
        xyz="0 0 0"
        rpy="0 0 0" />
      <geometry>
        <mesh
          filename="package://urdf_tutorial/meshes/thigh_link.STL" />
      </geometry>
      <material
        name="">
        <color
          rgba="0.752941176470588 0.752941176470588 0.752941176470588 1" />
      </material>
    </visual>
    <collision>
      <origin
        xyz="0 0 0"
        rpy="0 0 0" />
      <geometry>
        <mesh
          filename="package://urdf_tutorial/meshes/thigh_link.STL" />
      </geometry>
    </collision>
  </link>
  <joint
    name="RL_thigh_joint"
    type="revolute">
    <origin
      xyz="0 0.0974999999999997 0"
      rpy="0 -0.0393393013816893 0" />
    <parent
      link="RL_hip_link" />
    <child
      link="RL_thigh_link" />
    <axis
      xyz="0 1 0" />
    <limit
      lower="0"
      upper="0"
      effort="0"
      velocity="0" />
  </joint>
  <link
    name="RL_calf_link">
    <inertial>
      <origin
        xyz="0.00461061452147501 1.80400082941401E-06 -0.085011296004845"
        rpy="0 0 0" />
      <mass
        value="0.196508884495564" />
      <inertia
        ixx="0.00139217885927768"
        ixy="-2.06452748671354E-09"
        ixz="0.000125545815699013"
        iyy="0.00143103513567009"
        iyz="4.12063854261119E-08"
        izz="4.99156816168485E-05" />
    </inertial>
    <visual>
      <origin
        xyz="0 0 0"
        rpy="0 0 0" />
      <geometry>
        <mesh
          filename="package://urdf_tutorial/meshes/calf_link.STL" />
      </geometry>
      <material
        name="">
        <color
          rgba="0.898039215686275 0.917647058823529 0.929411764705882 1" />
      </material>
    </visual>
    <collision>
      <origin
        xyz="0 0 0"
        rpy="0 0 0" />
      <geometry>
        <mesh
          filename="package://urdf_tutorial/meshes/calf_link.STL" />
      </geometry>
    </collision>
  </link>
  <joint
    name="RL_calf_joint"
    type="revolute">
    <origin
      xyz="-0.00825912262911466 -0.00100000000000011 -0.209837524988717"
      rpy="0 0.0393393013816893 0" />
    <parent
      link="RL_thigh_link" />
    <child
      link="RL_calf_link" />
    <axis
      xyz="0 1 0" />
    <limit
      lower="0"
      upper="0"
      effort="0"
      velocity="0" />
  </joint>
  <link
    name="RL_foot_link">
    <inertial>
      <origin
        xyz="-0.0017545948682017 0 -0.00179543551506522"
        rpy="0 0 0" />
      <mass
        value="0.0332506166455944" />
      <inertia
        ixx="5.82412671981776E-06"
        ixy="-2.08372416049388E-22"
        ixz="6.37425175827703E-07"
        iyy="5.20120101015829E-06"
        iyz="-4.22786611841748E-22"
        izz="5.85346314748617E-06" />
    </inertial>
    <visual>
      <origin
        xyz="0 0 0"
        rpy="0 0 0" />
      <geometry>
        <mesh
          filename="package://urdf_tutorial/meshes/foot_link.STL" />
      </geometry>
      <material
        name="">
        <color
          rgba="0.298039215686275 0.298039215686275 0.298039215686275 1" />
      </material>
    </visual>
    <collision>
      <origin
        xyz="0 0 0"
        rpy="0 0 0" />
      <geometry>
        <mesh
          filename="package://urdf_tutorial/meshes/foot_link.STL" />
      </geometry>
    </collision>
  </link>
  <joint
    name="RL_foot_joint"
    type="fixed">
    <origin
      xyz="0 0 -0.215773231361156"
      rpy="0 0 0" />
    <parent
      link="RL_calf_link" />
    <child
      link="RL_foot_link" />
    <axis
      xyz="0 0 0" />
  </joint>
  <link
    name="RR_hip_link">
    <inertial>
      <origin
        xyz="0.0106669389296382 0.00105654727697253 8.09717352490136E-06"
        rpy="0 0 0" />
      <mass
        value="0.337657104489195" />
      <inertia
        ixx="0.00033566780997577"
        ixy="5.00830240333875E-06"
        ixz="3.5248031037544E-07"
        iyy="0.000441866858701045"
        iyz="1.15542052465266E-07"
        izz="0.000221750529456321" />
    </inertial>
    <visual>
      <origin
        xyz="0 0 0"
        rpy="0 0 0" />
      <geometry>
        <mesh
          filename="package://urdf_tutorial/meshes/R_hip_link.STL" />
      </geometry>
      <material
        name="">
        <color
          rgba="0.752941176470588 0.752941176470588 0.752941176470588 1" />
      </material>
    </visual>
    <collision>
      <origin
        xyz="0 0 0"
        rpy="0 0 0" />
      <geometry>
        <mesh
          filename="package://urdf_tutorial/meshes/R_hip_link.STL" />
      </geometry>
    </collision>
  </link>
  <joint
    name="RR_hip_joint"
    type="revolute">
    <origin
      xyz="-0.212000000000005 -0.057499999999997 0"
      rpy="0 0 0" />
    <parent
      link="base_link" />
    <child
      link="RR_hip_link" />
    <axis
      xyz="-1 0 0" />
    <limit
      lower="-3.14"
      upper="3.14"
      effort="100"
      velocity="100" />
  </joint>
  <link
    name="RR_thigh_link">
    <inertial>
      <origin
        xyz="-0.000517951191995464 0.0233673926041865 -0.028520257223253"
        rpy="0 0 0" />
      <mass
        value="0.981796539396402" />
      <inertia
        ixx="0.0025310851780392"
        ixy="1.75361348860848E-07"
        ixz="7.52244066710467E-06"
        iyy="0.00298771577306359"
        iyz="3.64975901054276E-06"
        izz="0.000652694084685766" />
    </inertial>
    <visual>
      <origin
        xyz="0 0 0"
        rpy="0 0 0" />
      <geometry>
        <mesh
          filename="package://urdf_tutorial/meshes/R_thigh_link.STL" />
      </geometry>
      <material
        name="">
        <color
          rgba="0.752941176470588 0.752941176470588 0.752941176470588 1" />
      </material>
    </visual>
    <collision>
      <origin
        xyz="0 0 0"
        rpy="0 0 0" />
      <geometry>
        <mesh
          filename="package://urdf_tutorial/meshes/R_thigh_link.STL" />
      </geometry>
    </collision>
  </link>
  <joint
    name="RR_thigh_joint"
    type="revolute">
    <origin
      xyz="0 -0.0975 0"
      rpy="0 0 0" />
    <parent
      link="RR_hip_link" />
    <child
      link="RR_thigh_link" />
    <axis
      xyz="0 -1 0" />
    <limit
      lower="-3.14"
      upper="3.14"
      effort="100"
      velocity="100" />
  </joint>
  <link
    name="RR_calf_link">
    <inertial>
      <origin
        xyz="0.00461061452147521 1.8040008296083E-06 -0.0850112960048445"
        rpy="0 0 0" />
      <mass
        value="0.196508884495562" />
      <inertia
        ixx="0.00139217885927767"
        ixy="-2.06452748588187E-09"
        ixz="0.000125545815699016"
        iyy="0.00143103513567006"
        iyz="4.12063854263401E-08"
        izz="4.99156816168366E-05" />
    </inertial>
    <visual>
      <origin
        xyz="0 0 0"
        rpy="0 0 0" />
      <geometry>
        <mesh
          filename="package://urdf_tutorial/meshes/calf_link.STL" />
      </geometry>
      <material
        name="">
        <color
          rgba="0.898039215686275 0.917647058823529 0.929411764705882 1" />
      </material>
    </visual>
    <collision>
      <origin
        xyz="0 0 0"
        rpy="0 0 0" />
      <geometry>
        <mesh
          filename="package://urdf_tutorial/meshes/calf_link.STL" />
      </geometry>
    </collision>
  </link>
  <joint
    name="RR_calf_joint"
    type="revolute">
    <origin
      xyz="0 0.001 -0.21"
      rpy="0 0 0" />
    <parent
      link="RR_thigh_link" />
    <child
      link="RR_calf_link" />
    <axis
      xyz="0 -1 0" />
    <limit
      lower="-3.14"
      upper="3.14"
      effort="100"
      velocity="100" />
  </joint>
  <link
    name="RR_foot_link">
    <inertial>
      <origin
        xyz="-0.0017545948682017 0 -0.00179543551506522"
        rpy="0 0 0" />
      <mass
        value="0.0332506166455944" />
      <inertia
        ixx="5.82412671981776E-06"
        ixy="-1.67264437396789E-23"
        ixz="6.37425175827701E-07"
        iyy="5.20120101015829E-06"
        iyz="4.9536863091819E-22"
        izz="5.85346314748617E-06" />
    </inertial>
    <visual>
      <origin
        xyz="0 0 0"
        rpy="0 0 0" />
      <geometry>
        <mesh
          filename="package://urdf_tutorial/meshes/foot_link.STL" />
      </geometry>
      <material
        name="">
        <color
          rgba="0.298039215686275 0.298039215686275 0.298039215686275 1" />
      </material>
    </visual>
    <collision>
      <origin
        xyz="0 0 0"
        rpy="0 0 0" />
      <geometry>
        <mesh
          filename="package://urdf_tutorial/meshes/foot_link.STL" />
      </geometry>
    </collision>
  </link>
  <joint
    name="RR_foot_joint"
    type="fixed">
    <origin
      xyz="0 0 -0.21577"
      rpy="0 0 0" />
    <parent
      link="RR_calf_link" />
    <child
      link="RR_foot_link" />
    <axis
      xyz="0 0 0" />
  </joint>
</robot>