<?xml version="1.0" encoding="utf-8"?>
<!-- This URDF was automatically created by SolidWorks to URDF Exporter! Originally created by Stephen Brawner (brawner@gmail.com) 
     Commit Version: 1.6.0-4-g7f85cfe  Build Version: 1.6.7995.38578
     For more information, please see http://wiki.ros.org/sw_urdf_exporter -->
<robot
  name="ASK-4-2">
  <link
    name="base_link">
    <inertial>
      <origin
        xyz="0.00992946630597228 -0.00266992153503952 0.00139568704685267"
        rpy="0 0 0" />
      <mass
        value="5.13967166144139" />
      <inertia
        ixx="0.0198344939840438"
        ixy="3.68855478958646E-05"
        ixz="-7.51002546313216E-05"
        iyy="0.0149462084052446"
        iyz="7.1656902141161E-05"
        izz="0.0263773506649489" />
    </inertial>
    <visual>
      <origin
        xyz="0 0 0"
        rpy="0 0 0" />
      <geometry>
        <mesh
          filename="package://ASK-4-2/meshes/base_link.STL" />
      </geometry>
      <material
        name="">
        <color
          rgba="0.752941176470588 0.752941176470588 0.752941176470588 1" />
      </material>
    </visual>
    <collision>
      <origin
        xyz="0 0 0"
        rpy="0 0 0" />
      <geometry>
        <mesh
          filename="package://ASK-4-2/meshes/base_link.STL" />
      </geometry>
    </collision>
  </link>
  <link
    name="FL_hip_link">
    <inertial>
      <origin
        xyz="-0.0106503457914954 -0.00105646187245095 7.50117564338182E-06"
        rpy="0 0 0" />
      <mass
        value="0.337654873921649" />
      <inertia
        ixx="0.000335612172323751"
        ixy="5.09865169622586E-06"
        ixz="3.45125064354634E-07"
        iyy="0.000441865005655587"
        iyz="2.04731987900165E-07"
        izz="0.000221802646140033" />
    </inertial>
    <visual>
      <origin
        xyz="0 0 0"
        rpy="0 0 0" />
      <geometry>
        <mesh
          filename="package://ASK-4-2/meshes/FL_hip_link.STL" />
      </geometry>
      <material
        name="">
        <color
          rgba="0.752941176470588 0.752941176470588 0.752941176470588 1" />
      </material>
    </visual>
    <collision>
      <origin
        xyz="0 0 0"
        rpy="0 0 0" />
      <geometry>
        <mesh
          filename="package://ASK-4-2/meshes/FL_hip_link.STL" />
      </geometry>
    </collision>
  </link>
  <joint
    name="FL_hip_joint"
    type="revolute">
    <origin
      xyz="0.209 0.0575 0"
      rpy="0 0 0" />
    <parent
      link="base_link" />
    <child
      link="FL_hip_link" />
    <axis
      xyz="1 0 0" />
    <limit
      lower="-3.14"
      upper="3.14"
      effort="100"
      velocity="100" />
  </joint>
  <link
    name="FL_thigh_link">
    <inertial>
      <origin
        xyz="-0.0270791915707163 0.0232842260903137 0.00998167182790227"
        rpy="0 0 0" />
      <mass
        value="0.98851736736006" />
      <inertia
        ixx="0.000985290178508422"
        ixy="1.98334149377828E-06"
        ixz="0.000721371260822831"
        iyy="0.00302059797548232"
        iyz="-1.13819293612705E-06"
        izz="0.00223151745206596" />
    </inertial>
    <visual>
      <origin
        xyz="0 0 0"
        rpy="0 0 0" />
      <geometry>
        <mesh
          filename="package://ASK-4-2/meshes/FL_thigh_link.STL" />
      </geometry>
      <material
        name="">
        <color
          rgba="0.752941176470588 0.752941176470588 0.752941176470588 1" />
      </material>
    </visual>
    <collision>
      <origin
        xyz="0 0 0"
        rpy="0 0 0" />
      <geometry>
        <mesh
          filename="package://ASK-4-2/meshes/FL_thigh_link.STL" />
      </geometry>
    </collision>
  </link>
  <joint
    name="FL_thigh_joint"
    type="revolute">
    <origin
      xyz="0 0.0975 0"
      rpy="-3.1416 -1.1642 0" />
    <parent
      link="FL_hip_link" />
    <child
      link="FL_thigh_link" />
    <axis
      xyz="0 -1 0" />
    <limit
      lower="-3.14"
      upper="3.14"
      effort="100"
      velocity="100" />
  </joint>
  <link
    name="FL_calf_link">
    <inertial>
      <origin
        xyz="0.00461061452147499 1.80400082966381E-06 -0.0850112960048441"
        rpy="0 0 0" />
      <mass
        value="0.196508884495562" />
      <inertia
        ixx="0.00139217885927767"
        ixy="-2.06452748568991E-09"
        ixz="0.000125545815699014"
        iyy="0.00143103513567007"
        iyz="4.12063854273975E-08"
        izz="4.9915681616853E-05" />
    </inertial>
    <visual>
      <origin
        xyz="0 0 0"
        rpy="0 0 0" />
      <geometry>
        <mesh
          filename="package://ASK-4-2/meshes/FL_calf_link.STL" />
      </geometry>
      <material
        name="">
        <color
          rgba="0.898039215686275 0.917647058823529 0.929411764705882 1" />
      </material>
    </visual>
    <collision>
      <origin
        xyz="0 0 0"
        rpy="0 0 0" />
      <geometry>
        <mesh
          filename="package://ASK-4-2/meshes/FL_calf_link.STL" />
      </geometry>
    </collision>
  </link>
  <joint
    name="FL_calf_joint"
    type="revolute">
    <origin
      xyz="-0.19288 0.001 0.083055"
      rpy="-3.1416 -1.1642 0" />
    <parent
      link="FL_thigh_link" />
    <child
      link="FL_calf_link" />
    <axis
      xyz="0 -1 0" />
    <limit
      lower="-3.14"
      upper="3.14"
      effort="100"
      velocity="100" />
  </joint>
  <link
    name="FL_foot_link">
    <inertial>
      <origin
        xyz="-0.00175459486820176 0 -0.00179543551506522"
        rpy="0 0 0" />
      <mass
        value="0.0332506166455944" />
      <inertia
        ixx="5.82412671981776E-06"
        ixy="6.40470714281943E-22"
        ixz="6.37425175827703E-07"
        iyy="5.20120101015828E-06"
        iyz="-1.55308179837147E-22"
        izz="5.85346314748617E-06" />
    </inertial>
    <visual>
      <origin
        xyz="0 0 0"
        rpy="0 0 0" />
      <geometry>
        <mesh
          filename="package://ASK-4-2/meshes/FL_foot_link.STL" />
      </geometry>
      <material
        name="">
        <color
          rgba="0.298039215686275 0.298039215686275 0.298039215686275 1" />
      </material>
    </visual>
    <collision>
      <origin
        xyz="0 0 0"
        rpy="0 0 0" />
      <geometry>
        <mesh
          filename="package://ASK-4-2/meshes/FL_foot_link.STL" />
      </geometry>
    </collision>
  </link>
  <joint
    name="FL_foot_joint"
    type="fixed">
    <origin
      xyz="0 0 -0.21577"
      rpy="0 0 0" />
    <parent
      link="FL_calf_link" />
    <child
      link="FL_foot_link" />
    <axis
      xyz="0 0 0" />
  </joint>
  <link
    name="FR_hip_link">
    <inertial>
      <origin
        xyz="-0.0106669389296382 0.00105654727697249 -8.09717352479034E-06"
        rpy="0 0 0" />
      <mass
        value="0.337657104489193" />
      <inertia
        ixx="0.000335667809975768"
        ixy="-5.0083024033389E-06"
        ixz="3.524803103757E-07"
        iyy="0.000441866858701043"
        iyz="-1.15542052465366E-07"
        izz="0.000221750529456321" />
    </inertial>
    <visual>
      <origin
        xyz="0 0 0"
        rpy="0 0 0" />
      <geometry>
        <mesh
          filename="package://ASK-4-2/meshes/FR_hip_link.STL" />
      </geometry>
      <material
        name="">
        <color
          rgba="0.752941176470588 0.752941176470588 0.752941176470588 1" />
      </material>
    </visual>
    <collision>
      <origin
        xyz="0 0 0"
        rpy="0 0 0" />
      <geometry>
        <mesh
          filename="package://ASK-4-2/meshes/FR_hip_link.STL" />
      </geometry>
    </collision>
  </link>
  <joint
    name="FR_hip_joint"
    type="revolute">
    <origin
      xyz="0.209 -0.0575 0"
      rpy="0 0 0" />
    <parent
      link="base_link" />
    <child
      link="FR_hip_link" />
    <axis
      xyz="1 0 0" />
    <limit
      lower="-3.14"
      upper="3.14"
      effort="100"
      velocity="100" />
  </joint>
  <link
    name="FR_thigh_link">
    <inertial>
      <origin
        xyz="0.000547030998780867 -0.023402103641135 -0.027687273549384"
        rpy="0 0 0" />
      <mass
        value="0.981796539065317" />
      <inertia
        ixx="0.00253399649841049"
        ixy="-7.20202567728191E-08"
        ixz="2.12505564364233E-05"
        iyy="0.00298771577286488"
        iyz="-4.13998861307807E-06"
        izz="0.000649782764080876" />
    </inertial>
    <visual>
      <origin
        xyz="0 0 0"
        rpy="0 0 0" />
      <geometry>
        <mesh
          filename="package://ASK-4-2/meshes/FR_thigh_link.STL" />
      </geometry>
      <material
        name="">
        <color
          rgba="0.752941176470588 0.752941176470588 0.752941176470588 1" />
      </material>
    </visual>
    <collision>
      <origin
        xyz="0 0 0"
        rpy="0 0 0" />
      <geometry>
        <mesh
          filename="package://ASK-4-2/meshes/FR_thigh_link.STL" />
      </geometry>
    </collision>
  </link>
  <joint
    name="FR_thigh_joint"
    type="revolute">
    <origin
      xyz="0 -0.10672 0"
      rpy="0 0 3.1416" />
    <parent
      link="FR_hip_link" />
    <child
      link="FR_thigh_link" />
    <axis
      xyz="0 1 0" />
    <limit
      lower="-3.14"
      upper="3.14"
      effort="100"
      velocity="100" />
  </joint>
  <link
    name="FR_calf_link">
    <inertial>
      <origin
        xyz="0.00461061452147515 1.80400082958054E-06 -0.085011296004845"
        rpy="0 0 0" />
      <mass
        value="0.196508884495563" />
      <inertia
        ixx="0.00139217885927768"
        ixy="-2.06452748628858E-09"
        ixz="0.000125545815699014"
        iyy="0.00143103513567007"
        iyz="4.12063854274795E-08"
        izz="4.9915681616835E-05" />
    </inertial>
    <visual>
      <origin
        xyz="0 0 0"
        rpy="0 0 0" />
      <geometry>
        <mesh
          filename="package://ASK-4-2/meshes/FR_calf_link.STL" />
      </geometry>
      <material
        name="">
        <color
          rgba="0.898039215686275 0.917647058823529 0.929411764705882 1" />
      </material>
    </visual>
    <collision>
      <origin
        xyz="0 0 0"
        rpy="0 0 0" />
      <geometry>
        <mesh
          filename="package://ASK-4-2/meshes/FR_calf_link.STL" />
      </geometry>
    </collision>
  </link>
  <joint
    name="FR_calf_joint"
    type="revolute">
    <origin
      xyz="0 -0.001 -0.21"
      rpy="0 0 -3.1416" />
    <parent
      link="FR_thigh_link" />
    <child
      link="FR_calf_link" />
    <axis
      xyz="0 -1 0" />
    <limit
      lower="-3.14"
      upper="3.14"
      effort="100"
      velocity="100" />
  </joint>
  <link
    name="FR_foot_link">
    <inertial>
      <origin
        xyz="-0.00175459486820179 2.77555756156289E-17 -0.00182803153806099"
        rpy="0 0 0" />
      <mass
        value="0.0332506166455944" />
      <inertia
        ixx="5.82412671981776E-06"
        ixy="1.61311277559526E-22"
        ixz="6.37425175827703E-07"
        iyy="5.20120101015828E-06"
        iyz="7.53908238435924E-22"
        izz="5.85346314748616E-06" />
    </inertial>
    <visual>
      <origin
        xyz="0 0 0"
        rpy="0 0 0" />
      <geometry>
        <mesh
          filename="package://ASK-4-2/meshes/FR_foot_link.STL" />
      </geometry>
      <material
        name="">
        <color
          rgba="0.298039215686275 0.298039215686275 0.298039215686275 1" />
      </material>
    </visual>
    <collision>
      <origin
        xyz="0 0 0"
        rpy="0 0 0" />
      <geometry>
        <mesh
          filename="package://ASK-4-2/meshes/FR_foot_link.STL" />
      </geometry>
    </collision>
  </link>
  <joint
    name="FR_foot_joint"
    type="fixed">
    <origin
      xyz="0 0 -0.21574"
      rpy="0 0 0" />
    <parent
      link="FR_calf_link" />
    <child
      link="FR_foot_link" />
    <axis
      xyz="0 0 0" />
  </joint>
  <link
    name="RL_hip_link">
    <inertial>
      <origin
        xyz="0.0106503460334455 -0.00105646148572416 -7.50181891534529E-06"
        rpy="0 0 0" />
      <mass
        value="0.33765486830875" />
      <inertia
        ixx="0.000335612160621357"
        ixy="-5.09864760893829E-06"
        ixz="3.45117707490452E-07"
        iyy="0.000441864990334726"
        iyz="-2.04736902744738E-07"
        izz="0.00022180263729175" />
    </inertial>
    <visual>
      <origin
        xyz="0 0 0"
        rpy="0 0 0" />
      <geometry>
        <mesh
          filename="package://ASK-4-2/meshes/RL_hip_link.STL" />
      </geometry>
      <material
        name="">
        <color
          rgba="0.752941176470588 0.752941176470588 0.752941176470588 1" />
      </material>
    </visual>
    <collision>
      <origin
        xyz="0 0 0"
        rpy="0 0 0" />
      <geometry>
        <mesh
          filename="package://ASK-4-2/meshes/RL_hip_link.STL" />
      </geometry>
    </collision>
  </link>
  <joint
    name="RL_hip_joint"
    type="revolute">
    <origin
      xyz="-0.212 0.0575 0"
      rpy="0 0 0" />
    <parent
      link="base_link" />
    <child
      link="RL_hip_link" />
    <axis
      xyz="-1 0 0" />
    <limit
      lower="-3.14"
      upper="3.14"
      effort="100"
      velocity="100" />
  </joint>
  <link
    name="RL_thigh_link">
    <inertial>
      <origin
        xyz="0.00040822764833115 0.0232833165047042 -0.0284358552532086"
        rpy="0 0 0" />
      <mass
        value="0.988547565628563" />
      <inertia
        ixx="0.00255264500112588"
        ixy="-9.86657315843123E-07"
        ixz="9.82930312945563E-05"
        iyy="0.00302059853537962"
        iyz="2.68895979718321E-06"
        izz="0.000664162957356032" />
    </inertial>
    <visual>
      <origin
        xyz="0 0 0"
        rpy="0 0 0" />
      <geometry>
        <mesh
          filename="package://ASK-4-2/meshes/RL_thigh_link.STL" />
      </geometry>
      <material
        name="">
        <color
          rgba="0.752941176470588 0.752941176470588 0.752941176470588 1" />
      </material>
    </visual>
    <collision>
      <origin
        xyz="0 0 0"
        rpy="0 0 0" />
      <geometry>
        <mesh
          filename="package://ASK-4-2/meshes/RL_thigh_link.STL" />
      </geometry>
    </collision>
  </link>
  <joint
    name="RL_thigh_joint"
    type="revolute">
    <origin
      xyz="0 0.0975 0"
      rpy="0 0.039339 3.1416" />
    <parent
      link="RL_hip_link" />
    <child
      link="RL_thigh_link" />
    <axis
      xyz="0 -1 0" />
    <limit
      lower="0"
      upper="0"
      effort="0"
      velocity="0" />
  </joint>
  <link
    name="RL_calf_link">
    <inertial>
      <origin
        xyz="0.00461061452147504 1.80400082946952E-06 -0.0850112960048451"
        rpy="0 0 0" />
      <mass
        value="0.196508884495564" />
      <inertia
        ixx="0.00139217885927768"
        ixy="-2.06452748671305E-09"
        ixz="0.000125545815699013"
        iyy="0.00143103513567009"
        iyz="4.12063854261163E-08"
        izz="4.99156816168485E-05" />
    </inertial>
    <visual>
      <origin
        xyz="0 0 0"
        rpy="0 0 0" />
      <geometry>
        <mesh
          filename="package://ASK-4-2/meshes/RL_calf_link.STL" />
      </geometry>
      <material
        name="">
        <color
          rgba="0.898039215686275 0.917647058823529 0.929411764705882 1" />
      </material>
    </visual>
    <collision>
      <origin
        xyz="0 0 0"
        rpy="0 0 0" />
      <geometry>
        <mesh
          filename="package://ASK-4-2/meshes/RL_calf_link.STL" />
      </geometry>
    </collision>
  </link>
  <joint
    name="RL_calf_joint"
    type="revolute">
    <origin
      xyz="0.0082591 0.001 -0.20984"
      rpy="0 0.039339 3.1416" />
    <parent
      link="RL_thigh_link" />
    <child
      link="RL_calf_link" />
    <axis
      xyz="0 -1 0" />
    <limit
      lower="0"
      upper="0"
      effort="0"
      velocity="0" />
  </joint>
  <link
    name="RL_foot_link">
    <inertial>
      <origin
        xyz="-0.0017545948682017 0 -0.00179543551506522"
        rpy="0 0 0" />
      <mass
        value="0.0332506166455944" />
      <inertia
        ixx="5.82412671981776E-06"
        ixy="-2.08372416049388E-22"
        ixz="6.37425175827703E-07"
        iyy="5.20120101015829E-06"
        iyz="-4.22786611841748E-22"
        izz="5.85346314748617E-06" />
    </inertial>
    <visual>
      <origin
        xyz="0 0 0"
        rpy="0 0 0" />
      <geometry>
        <mesh
          filename="package://ASK-4-2/meshes/RL_foot_link.STL" />
      </geometry>
      <material
        name="">
        <color
          rgba="0.298039215686275 0.298039215686275 0.298039215686275 1" />
      </material>
    </visual>
    <collision>
      <origin
        xyz="0 0 0"
        rpy="0 0 0" />
      <geometry>
        <mesh
          filename="package://ASK-4-2/meshes/RL_foot_link.STL" />
      </geometry>
    </collision>
  </link>
  <joint
    name="RL_foot_joint"
    type="fixed">
    <origin
      xyz="0 0 -0.21577"
      rpy="0 0 0" />
    <parent
      link="RL_calf_link" />
    <child
      link="RL_foot_link" />
    <axis
      xyz="0 0 0" />
  </joint>
  <link
    name="RR_hip_link">
    <inertial>
      <origin
        xyz="0.0106669389296382 0.00105654727697253 8.09717352490136E-06"
        rpy="0 0 0" />
      <mass
        value="0.337657104489195" />
      <inertia
        ixx="0.00033566780997577"
        ixy="5.00830240333875E-06"
        ixz="3.52480310375442E-07"
        iyy="0.000441866858701045"
        iyz="1.15542052465261E-07"
        izz="0.000221750529456321" />
    </inertial>
    <visual>
      <origin
        xyz="0 0 0"
        rpy="0 0 0" />
      <geometry>
        <mesh
          filename="package://ASK-4-2/meshes/RR_hip_link.STL" />
      </geometry>
      <material
        name="">
        <color
          rgba="0.752941176470588 0.752941176470588 0.752941176470588 1" />
      </material>
    </visual>
    <collision>
      <origin
        xyz="0 0 0"
        rpy="0 0 0" />
      <geometry>
        <mesh
          filename="package://ASK-4-2/meshes/RR_hip_link.STL" />
      </geometry>
    </collision>
  </link>
  <joint
    name="RR_hip_joint"
    type="revolute">
    <origin
      xyz="-0.212 -0.0575 0"
      rpy="0 0 0" />
    <parent
      link="base_link" />
    <child
      link="RR_hip_link" />
    <axis
      xyz="-1 0 0" />
    <limit
      lower="-3.14"
      upper="3.14"
      effort="100"
      velocity="100" />
  </joint>
  <link
    name="RR_thigh_link">
    <inertial>
      <origin
        xyz="-0.000517949515534272 0.0233673926092961 -0.0285202548691598"
        rpy="0 0 0" />
      <mass
        value="0.981796539186015" />
      <inertia
        ixx="0.00253108517800814"
        ixy="1.75361289018903E-07"
        ixz="7.52244067642052E-06"
        iyy="0.00298771577291471"
        iyz="3.64975900668205E-06"
        izz="0.000652694084517526" />
    </inertial>
    <visual>
      <origin
        xyz="0 0 0"
        rpy="0 0 0" />
      <geometry>
        <mesh
          filename="package://ASK-4-2/meshes/RR_thigh_link.STL" />
      </geometry>
      <material
        name="">
        <color
          rgba="0.752941176470588 0.752941176470588 0.752941176470588 1" />
      </material>
    </visual>
    <collision>
      <origin
        xyz="0 0 0"
        rpy="0 0 0" />
      <geometry>
        <mesh
          filename="package://ASK-4-2/meshes/RR_thigh_link.STL" />
      </geometry>
    </collision>
  </link>
  <joint
    name="RL_thigh_joint"
    type="revolute">
    <origin
      xyz="0 -0.0975 0"
      rpy="0 0 0" />
    <parent
      link="RR_hip_link" />
    <child
      link="RR_thigh_link" />
    <axis
      xyz="0 -1 0" />
    <limit
      lower="-3.14"
      upper="3.14"
      effort="100"
      velocity="100" />
  </joint>
  <link
    name="RR_calf_link">
    <inertial>
      <origin
        xyz="0.00461061447083067 1.80399490780359E-06 -0.0850112957227415"
        rpy="0 0 0" />
      <mass
        value="0.196508883743766" />
      <inertia
        ixx="0.00139217885498652"
        ixy="-2.06450991178106E-09"
        ixz="0.000125545814906742"
        iyy="0.00143103513123057"
        iyz="4.12062920205897E-08"
        izz="4.99156814648132E-05" />
    </inertial>
    <visual>
      <origin
        xyz="0 0 0"
        rpy="0 0 0" />
      <geometry>
        <mesh
          filename="package://ASK-4-2/meshes/RR_calf_link.STL" />
      </geometry>
      <material
        name="">
        <color
          rgba="0.898039215686275 0.917647058823529 0.929411764705882 1" />
      </material>
    </visual>
    <collision>
      <origin
        xyz="0 0 0"
        rpy="0 0 0" />
      <geometry>
        <mesh
          filename="package://ASK-4-2/meshes/RR_calf_link.STL" />
      </geometry>
    </collision>
  </link>
  <joint
    name="RR_calf_joint"
    type="revolute">
    <origin
      xyz="0 0.001 -0.21"
      rpy="0 0 0" />
    <parent
      link="RR_thigh_link" />
    <child
      link="RR_calf_link" />
    <axis
      xyz="0 -1 0" />
    <limit
      lower="-3.14"
      upper="3.14"
      effort="100"
      velocity="100" />
  </joint>
  <link
    name="RR_foot_link">
    <inertial>
      <origin
        xyz="-0.00175459486820173 0 -0.00179543551506522"
        rpy="0 0 0" />
      <mass
        value="0.0332506166455944" />
      <inertia
        ixx="5.82412671981776E-06"
        ixy="-1.89451746978622E-23"
        ixz="6.37425175827702E-07"
        iyy="5.20120101015829E-06"
        iyz="5.69730337151966E-22"
        izz="5.85346314748617E-06" />
    </inertial>
    <visual>
      <origin
        xyz="0 0 0"
        rpy="0 0 0" />
      <geometry>
        <mesh
          filename="package://ASK-4-2/meshes/RR_foot_link.STL" />
      </geometry>
      <material
        name="">
        <color
          rgba="0.298039215686275 0.298039215686275 0.298039215686275 1" />
      </material>
    </visual>
    <collision>
      <origin
        xyz="0 0 0"
        rpy="0 0 0" />
      <geometry>
        <mesh
          filename="package://ASK-4-2/meshes/RR_foot_link.STL" />
      </geometry>
    </collision>
  </link>
  <joint
    name="RR_foot_joint"
    type="fixed">
    <origin
      xyz="0 0 -0.21577"
      rpy="0 0 0" />
    <parent
      link="RR_calf_link" />
    <child
      link="RR_foot_link" />
    <axis
      xyz="0 0 0" />
  </joint>
</robot>